Workbook
Name Slicer_Month_Name: #N/A
Name Slicer_region: #N/A
Name Slicer_Year: #N/A

Sheet Trend
C2: gross_revenue | D2: Total Net Revenue | E2: Returned Revenue | F2: Total Orders | G2: Total Customers | H2: AOV | K2: total_customers
C3: 3611796.5 | D3: 3344695.8 | E3: 267100.71 | F3: 5066 | G3: 1411 | H3: 712.94837 | K3: 2630
X7: Net Revenue Details - Order Year: | Y7: =$I$23 -> 2025 | AK7: Total Orders Details - Order Year: | AM7: =I23 -> 2025
B8: Helper | C8: Year | D8: net_revenue | E8: net_revenue_LY | F8: YoY_net_revenue_var | G8: %_YoY_net_revenue_var | O8: Helper | P8: Year | Q8: Month Name | R8: net_revenue | S8: net_revenue_PM | T8: MoM_net_revenue_var | U8: %_MoM_net_revenue_var | W8: Order Month | X8: Net Revenue | Y8: Net Revenue PM | Z8: MoM Variance | AA8: % MoM Variance | AC8: Helper | AD8: Year | AE8: Month Name | AF8: total_orders | AG8: total_orders_PM | AH8: MoM_total_orders_var | AI8: %_MoM_orders_var | AK8: Order Month | AL8: MoM Variance | AM8: % MoM Variance
B9: 1 | C9: 2023 | D9: 3252652 | O9: 1 | P9: 2025 | Q9: Jan | R9: 295336.42 | S9: 233629.02 | T9: 61707.4 | U9: 0.26412558 | W9: =Q9 -> Jan | X9: =R9 -> 295336.42 | Y9: =S9 -> 233629.02 | Z9: =T9 -> 61707.4 | AA9: =U9 -> 0.26412558 | AC9: 1 | AD9: 2025 | AE9: Jan | AF9: 480 | AG9: 351 | AH9: 129 | AI9: 0.36752137 | AK9: =AE9 -> Jan | AL9: =AH9 -> 129 | AM9: =AI9 -> 0.36752137
B10: 2 | C10: 2024 | D10: 3156323.3 | E10: 3252652 | F10: -96328.73 | G10: -0.029615443 | O10: 2 | Q10: Feb | R10: 265354.18 | S10: 295336.42 | T10: -29982.24 | U10: -0.10151894 | W10: =Q10 -> Feb | X10: =R10 -> 265354.18 | Y10: =S10 -> 295336.42 | Z10: =T10 -> -29982.24 | AA10: =U10 -> -0.10151894 | AC10: 2 | AE10: Feb | AF10: 379 | AG10: 480 | AH10: -101 | AI10: -0.21041667 | AK10: =AE10 -> Feb | AL10: =AH10 -> -101 | AM10: =AI10 -> -0.21041667
B11: 3 | C11: 2025 | D11: 3344695.8 | E11: 3156323.3 | F11: 188372.46 | G11: 0.059680978 | O11: 3 | Q11: Mar | R11: 322144.6 | S11: 265354.18 | T11: 56790.42 | U11: 0.21401743 | W11: =Q11 -> Mar | X11: =R11 -> 322144.6 | Y11: =S11 -> 265354.18 | Z11: =T11 -> 56790.42 | AA11: =U11 -> 0.21401743 | AC11: 3 | AE11: Mar | AF11: 441 | AG11: 379 | AH11: 62 | AI11: 0.16358839 | AK11: =AE11 -> Mar | AL11: =AH11 -> 62 | AM11: =AI11 -> 0.16358839
B12: 4 | C12: 2026 | D12: 56049.63 | E12: 3344695.8 | F12: -3288646.1 | G12: -0.98324223 | O12: 4 | Q12: Apr | R12: 277569.76 | S12: 322144.6 | T12: -44574.84 | U12: -0.13836904 | W12: =Q12 -> Apr | X12: =R12 -> 277569.76 | Y12: =S12 -> 322144.6 | Z12: =T12 -> -44574.84 | AA12: =U12 -> -0.13836904 | AC12: 4 | AE12: Apr | AF12: 378 | AG12: 441 | AH12: -63 | AI12: -0.14285714 | AK12: =AE12 -> Apr | AL12: =AH12 -> -63 | AM12: =AI12 -> -0.14285714
O13: 5 | Q13: May | R13: 277890.63 | S13: 277569.76 | T13: 320.87 | U13: 0.0011559977 | W13: =Q13 -> May | X13: =R13 -> 277890.63 | Y13: =S13 -> 277569.76 | Z13: =T13 -> 320.87 | AA13: =U13 -> 0.0011559977 | AC13: 5 | AE13: May | AF13: 419 | AG13: 378 | AH13: 41 | AI13: 0.10846561 | AK13: =AE13 -> May | AL13: =AH13 -> 41 | AM13: =AI13 -> 0.10846561
B14: Helper | C14: Year | D14: total_orders | E14: total_orders_LY | F14: YoY_total_orders_var | G14: %_YoY_total_orders_var | O14: 6 | Q14: Jun | R14: 301505.29 | S14: 277890.63 | T14: 23614.66 | U14: 0.084978252 | W14: =Q14 -> Jun | X14: =R14 -> 301505.29 | Y14: =S14 -> 277890.63 | Z14: =T14 -> 23614.66 | AA14: =U14 -> 0.084978252 | AC14: 6 | AE14: Jun | AF14: 448 | AG14: 419 | AH14: 29 | AI14: 0.069212411 | AK14: =AE14 -> Jun | AL14: =AH14 -> 29 | AM14: =AI14 -> 0.069212411
B15: 1 | C15: 2023 | D15: 4873 | O15: 7 | Q15: Jul | R15: 262884.66 | S15: 301505.29 | T15: -38620.63 | U15: -0.12809271 | W15: =Q15 -> Jul | X15: =R15 -> 262884.66 | Y15: =S15 -> 301505.29 | Z15: =T15 -> -38620.63 | AA15: =U15 -> -0.12809271 | AC15: 7 | AE15: Jul | AF15: 414 | AG15: 448 | AH15: -34 | AI15: -0.075892857 | AK15: =AE15 -> Jul | AL15: =AH15 -> -34 | AM15: =AI15 -> -0.075892857
B16: 2 | C16: 2024 | D16: 4974 | E16: 4873 | F16: 101 | G16: 0.020726452 | O16: 8 | Q16: Aug | R16: 240929.68 | S16: 262884.66 | T16: -21954.98 | U16: -0.083515638 | W16: =Q16 -> Aug | X16: =R16 -> 240929.68 | Y16: =S16 -> 262884.66 | Z16: =T16 -> -21954.98 | AA16: =U16 -> -0.083515638 | AC16: 8 | AE16: Aug | AF16: 414 | AG16: 414 | AH16: 0 | AK16: =AE16 -> Aug | AL16: =AH16 -> 0 | AM16: =AI16 -> 0
B17: 3 | C17: 2025 | D17: 5066 | E17: 4974 | F17: 92 | G17: 0.01849618 | O17: 9 | Q17: Sep | R17: 288266.25 | S17: 240929.68 | T17: 47336.57 | U17: 0.19647463 | W17: =Q17 -> Sep | X17: =R17 -> 288266.25 | Y17: =S17 -> 240929.68 | Z17: =T17 -> 47336.57 | AA17: =U17 -> 0.19647463 | AC17: 9 | AE17: Sep | AF17: 427 | AG17: 414 | AH17: 13 | AI17: 0.031400966 | AK17: =AE17 -> Sep | AL17: =AH17 -> 13 | AM17: =AI17 -> 0.031400966
B18: 4 | C18: 2026 | D18: 87 | E18: 5066 | F18: -4979 | G18: -0.98282669 | O18: 10 | Q18: Oct | R18: 305935.78 | S18: 288266.25 | T18: 17669.53 | U18: 0.061295868 | W18: =Q18 -> Oct | X18: =R18 -> 305935.78 | Y18: =S18 -> 288266.25 | Z18: =T18 -> 17669.53 | AA18: =U18 -> 0.061295868 | AC18: 10 | AE18: Oct | AF18: 469 | AG18: 427 | AH18: 42 | AI18: 0.098360656 | AK18: =AE18 -> Oct | AL18: =AH18 -> 42 | AM18: =AI18 -> 0.098360656
O19: 11 | Q19: Nov | R19: 251103.46 | S19: 305935.78 | T19: -54832.32 | U19: -0.1792282 | W19: =Q19 -> Nov | X19: =R19 -> 251103.46 | Y19: =S19 -> 305935.78 | Z19: =T19 -> -54832.32 | AA19: =U19 -> -0.1792282 | AC19: 11 | AE19: Nov | AF19: 395 | AG19: 469 | AH19: -74 | AI19: -0.15778252 | AK19: =AE19 -> Nov | AL19: =AH19 -> -74 | AM19: =AI19 -> -0.15778252
O20: 12 | Q20: Dec | R20: 255775.04 | S20: 251103.46 | T20: 4671.58 | U20: 0.018604204 | W20: =Q20 -> Dec | X20: =R20 -> 255775.04 | Y20: =S20 -> 251103.46 | Z20: =T20 -> 4671.58 | AA20: =U20 -> 0.018604204 | AC20: 12 | AE20: Dec | AF20: 402 | AG20: 395 | AH20: 7 | AI20: 0.017721519 | AK20: =AE20 -> Dec | AL20: =AH20 -> 7 | AM20: =AI20 -> 0.017721519
A21: Pstn | B21: LY | C21: CY | D21: Net Revenue | E21: Last Year Net Revenue | F21: YoY Variance | G21: % YoY Variance | P21: 2025 Total | R21: 3344695.8 | S21: 233629.02 | T21: 3111066.7 | U21: 13.316268 | AD21: 2025 Total | AF21: 5066 | AG21: 351 | AH21: 4715 | AI21: 13.433048
A22: =MATCH($I$23,$C$9:$C$12,0)-1 -> 2 | B22: {=IF($I$23=MIN(C9:C12),"",INDEX($C$9:$C$12,$A$22))} -> 2024 | C22: =I23 -> 2025 | D22: =VLOOKUP($C$22,$C$9:$G$12,2,0) -> 3344695.8 | E22: =VLOOKUP($C$22,$C$9:$G$12,3,0) -> 3156323.3 | F22: =VLOOKUP($C$22,$C$9:$G$12,4,0) -> 188372.46 | G22: =VLOOKUP($C$22,$C$9:$G$12,5,0) -> 0.059680978 | I22: Year | L22: Month Name | W22: =X7 -> Net Revenue Details - Order Year: | X22: =Y7 -> 2025
I23: 2025 | L23: Jun | W23: =W8 -> Order Month | X23: =X8 -> Net Revenue | Z23: =X7 -> Net Revenue Details - Order Year: | AB23: =Y7 -> 2025 | AK23: =AK8 -> Order Month | AL23: =AL8 -> MoM Variance
W24: =W9 -> Jan | X24: =X9 -> 295336.42 | Z24: =W8 -> Order Month | AA24: =Z8 -> MoM Variance | AB24: =AA8 -> % MoM Variance | AK24: =AK9 -> Jan | AL24: =AL9 -> 129
A25: Pstn | B25: CY | C25: PM | D25: CM | E25: Net Revenue | F25: Pre Month Net Revenue | G25: MoM Variance | H25: % MoM Variance | W25: =W10 -> Feb | X25: =X10 -> 265354.18 | Z25: =W9 -> Jan | AA25: =Z9 -> 61707.4 | AB25: =AA9 -> 0.26412558 | AK25: =AK10 -> Feb | AL25: =AL10 -> -101
A26: =MATCH($L$23,$Q$9:$Q$20,0)-1 -> 5 | B26: =$I$23 -> 2025 | C26: {=IF($D$26 = "Jan","", INDEX($Q$9:$Q$20,$A$26))} -> May | D26: =L23 -> Jun | E26: =IF(AND($C$26="",$B$26=MIN($C$9:$C$12)),$R$9,VLOOKUP($D$26,$Q$9:$U$20,2,0)) -> 301505.29 | F26: =IF(AND($C$26="",$B$26=MIN($C$9:$C$12)),TEXT(0,"$0.00"),VLOOKUP($D$26,$Q$9:$U$20,3,0)) -> 277890.63 | G26: =IF(AND($C$26="",$B$26=MIN($C$9:$C$12)),TEXT(0,"$0.00"),VLOOKUP($D$26,$Q$9:$U$20,4,0)) -> 23614.66 | H26: =IF(AND($C$26="",$B$26=MIN($C$9:$C$12)),TEXT(0,"0.00%"),VLOOKUP($D$26,$Q$9:$U$20,5,0)) -> 0.084978252 | W26: =W11 -> Mar | X26: =X11 -> 322144.6 | Z26: =W10 -> Feb | AA26: =Z10 -> -29982.24 | AB26: =AA10 -> -0.10151894 | AK26: =AK11 -> Mar | AL26: =AL11 -> 62
W27: =W12 -> Apr | X27: =X12 -> 277569.76 | Z27: =W11 -> Mar | AA27: =Z11 -> 56790.42 | AB27: =AA11 -> 0.21401743 | AK27: =AK12 -> Apr | AL27: =AL12 -> -63
W28: =W13 -> May | X28: =X13 -> 277890.63 | Z28: =W12 -> Apr | AA28: =Z12 -> -44574.84 | AB28: =AA12 -> -0.13836904 | AK28: =AK13 -> May | AL28: =AL13 -> 41
A29: Pstn | B29: LY | C29: CY | D29: Orders | E29: Last Year Orders | F29: YoY Variance | G29: % YoY Variance | W29: =W14 -> Jun | X29: =X14 -> 301505.29 | Z29: =W13 -> May | AA29: =Z13 -> 320.87 | AB29: =AA13 -> 0.0011559977 | AK29: =AK14 -> Jun | AL29: =AL14 -> 29
A30: =MATCH($I$23,$C$9:$C$12,0)-1 -> 2 | B30: {=IF($I$23=MIN(C15:C18),"",INDEX($C$9:$C$12,$A$22))} -> 2024 | C30: =$I$23 -> 2025 | D30: =VLOOKUP($C$30,$C$15:$G$18,2,0) -> 5066 | E30: =VLOOKUP($C$30,$C$15:$G$18,3,0) -> 4974 | F30: =VLOOKUP($C$30,$C$15:$G$18,4,0) -> 92 | G30: =VLOOKUP($C$30,$C$15:$G$18,5,0) -> 0.01849618 | W30: =W15 -> Jul | X30: =X15 -> 262884.66 | Z30: =W14 -> Jun | AA30: =Z14 -> 23614.66 | AB30: =AA14 -> 0.084978252 | AK30: =AK15 -> Jul | AL30: =AL15 -> -34
W31: =W16 -> Aug | X31: =X16 -> 240929.68 | Z31: =W15 -> Jul | AA31: =Z15 -> -38620.63 | AB31: =AA15 -> -0.12809271 | AK31: =AK16 -> Aug | AL31: =AL16 -> 0
W32: =W17 -> Sep | X32: =X17 -> 288266.25 | Z32: =W16 -> Aug | AA32: =Z16 -> -21954.98 | AB32: =AA16 -> -0.083515638 | AK32: =AK17 -> Sep | AL32: =AL17 -> 13
A33: Pstn | B33: CY | C33: PM | D33: CM | E33: Orders | F33: Previous Month Orders | G33: MoM Variance | H33: % MoM Variance | W33: =W18 -> Oct | X33: =X18 -> 305935.78 | Z33: =W17 -> Sep | AA33: =Z17 -> 47336.57 | AB33: =AA17 -> 0.19647463 | AK33: =AK18 -> Oct | AL33: =AL18 -> 42
A34: =MATCH($L$23,$Q$9:$Q$20,0)-1 -> 5 | B34: =$I$23 -> 2025 | C34: {=IF($D$34 = "Jan","", INDEX($AE$9:$AE$20,$A$34))} -> May | D34: =$L$23 -> Jun | E34: =IF(AND($C$34="",$B$34=MIN($C$15:$C$18)),$AF$9,VLOOKUP($D$34,$AE$9:$AI$20,2,0)) -> 448 | F34: =IF(AND($C$34="",$B$34=MIN($C$15:$C$18)),TEXT(0,"$0.00"),VLOOKUP($D$34,$AE$9:$AI$20,3,0)) -> 419 | G34: =IF(AND($C$34="",$B$34=MIN($C$15:$C$18)),TEXT(0,"$0.00"),VLOOKUP($D$34,$AE$9:$AI$20,4,0)) -> 29 | H34: =IF(AND($C$34="",$B$34=MIN($C$15:$C$18)),TEXT(0,"0.00%"),VLOOKUP($D$34,$AE$9:$AI$20,5,0)) -> 0.069212411 | W34: =W19 -> Nov | X34: =X19 -> 251103.46 | Z34: =W18 -> Oct | AA34: =Z18 -> 17669.53 | AB34: =AA18 -> 0.061295868 | AK34: =AK19 -> Nov | AL34: =AL19 -> -74
W35: =W20 -> Dec | X35: =X20 -> 255775.04 | Z35: =W19 -> Nov | AA35: =Z19 -> -54832.32 | AB35: =AA19 -> -0.1792282 | AK35: =AK20 -> Dec | AL35: =AL20 -> 7
Z36: =W20 -> Dec | AA36: =Z20 -> 4671.58 | AB36: =AA20 -> 0.018604204
D38: TITLE | E38: ="Monthly Net Revenue: " &Y7 -> Monthly Net Revenue: 2025 | W38: ="Monthly Orders Trend: " & I23 -> Monthly Orders Trend: 2025 | Z38: =Z24 -> Order Month | AA38: =AA24 -> MoM Variance
W39: Order Month | X39: Orders | Z39: =Z25 -> Jan | AA39: =AA25 -> 61707.4
W40: =W25 -> Feb | X40: =AF9 -> 480 | Z40: =Z26 -> Feb | AA40: =AA26 -> -29982.24
W41: =W26 -> Mar | X41: =AF10 -> 379 | Z41: =Z27 -> Mar | AA41: =AA27 -> 56790.42
W42: =W27 -> Apr | X42: =AF11 -> 441 | Z42: =Z28 -> Apr | AA42: =AA28 -> -44574.84 | AL42: ="MoM Net revenue Variance: " &I23 -> MoM Net revenue Variance: 2025
W43: =W28 -> May | X43: =AF12 -> 378 | Z43: =Z29 -> May | AA43: =AA29 -> 320.87
W44: =W29 -> Jun | X44: =AF13 -> 419 | Z44: =Z30 -> Jun | AA44: =AA30 -> 23614.66
W45: =W30 -> Jul | X45: =AF14 -> 448 | Z45: =Z31 -> Jul | AA45: =AA31 -> -38620.63
...

Sheet Churn and Repeated
E3: Pstn | F3: PY | G3: Year | H3: total_customers_to_date | I3: churned_customers | J3: churn_rate | K3: Previous Year Rate | L3: YoY Variance
E4: =MATCH($G$4,$B$7:$B$10,0)-1 -> 2 | F4: {=IF($G$4=2023,"",INDEX($B$7:$B$10,$E$4))} -> 2024 | G4: =I7 -> 2025 | H4: =VLOOKUP($G$4,$B$7:$G$10,2,0) -> 2623 | I4: =VLOOKUP($G$4,$B$7:$G$10,3,0) -> 516 | J4: =VLOOKUP($G$4,$B$7:$G$10,4,0) -> 0.19672131 | K4: =VLOOKUP($G$4,$B$7:$G$10,5,0) -> 0.24392523 | L4: =VLOOKUP($G$4,$B$7:$G$10,6,0) -> -0.047203922
A6: Helper | B6: Year | C6: total_customers_to_date | D6: churned_customers | E6: churn_rate | F6: Previous Year Rate | G6: YoY_Var | I6: Year
A7: 1 | B7: 2023 | C7: =C15 -> 1391 | D7: =D15 -> 492 | E7: =E15 -> 0.35370237 | I7: 2025
A8: 2 | B8: 2024 | C8: =C16 -> 2140 | D8: =D16 -> 522 | E8: =E16 -> 0.24392523 | F8: =$E7 -> 0.35370237 | G8: =E8-F8 -> -0.10977714
A9: 3 | B9: 2025 | C9: =C17 -> 2623 | D9: =D17 -> 516 | E9: =E17 -> 0.19672131 | F9: =$E8 -> 0.24392523 | G9: =E9-F9 -> -0.047203922 | O9: ="Repeated Vs One-Time Customers: " &S26 -> Repeated Vs One-Time Customers: 2025
A10: 4 | B10: 2026 | C10: =C18 -> 2630 | D10: =D18 -> 0 | E10: =E18 -> 0 | O10: =P12+P13 -> 261
L12: customer_id | M12: Count of customer_id | N12: Count of order_id | O12: Repeated Customers | P12: =COUNTIF($M$13:$M$2642,">1") -> 49 | S12: Year | T12: total_customers | U12: repeated_purchases | V12: repeat_purchase_rate
L13: C00061 | M13: 1 | N13: 1 | O13: One time Customers | P13: =COUNTIF($M$13:$M$2642,"<=1") -> 212 | S13: 2023 | T13: 1391 | U13: 528 | V13: 0.37958303
B14: Year | C14: total_customers_to_date | D14: churned_customers | E14: churn_rate | L14: C00068 | M14: 1 | N14: 1 | S14: 2024 | T14: 1451 | U14: 519 | V14: 0.35768436
B15: 2023 | C15: 1391 | D15: 492 | E15: 0.35370237 | L15: C00079 | M15: 3 | N15: 3 | S15: 2025 | T15: 1411 | U15: 550 | V15: 0.38979447
B16: 2024 | C16: 2140 | D16: 522 | E16: 0.24392523 | L16: C00090 | M16: 1 | N16: 1 | S16: 2026 | T16: 68 | U16: 12 | V16: 0.17647059
B17: 2025 | C17: 2623 | D17: 516 | E17: 0.19672131 | L17: C00098 | M17: 1 | N17: 1 | S17: Grand Total | T17: 2630 | U17: 1392 | V17: 0.52927757
B18: 2026 | C18: 2630 | D18: 0 | E18: 0 | L18: C00133 | M18: 1 | N18: 1
L19: C00159 | M19: 3 | N19: 3 | R19: Helper | S19: Year | T19: total_customers | U19: repeated_purchases | V19: repeat_purchase_rate | W19: Previous Year Rate | X19: YoY_Var
L20: C00189 | M20: 2 | N20: 2 | R20: 1 | S20: 2023 | T20: =T13 -> 1391 | U20: =U13 -> 528 | V20: =V13 -> 0.37958303
L21: C00208 | M21: 2 | N21: 2 | R21: 2 | S21: 2024 | T21: =T14 -> 1451 | U21: =U14 -> 519 | V21: =V14 -> 0.35768436 | W21: =V20 -> 0.37958303 | X21: =V21-W21 -> -0.021898678
B22: customer_id | C22: last_purchase_date | L22: C00263 | M22: 1 | N22: 1 | R22: 3 | S22: 2025 | T22: =T15 -> 1411 | U22: =U15 -> 550 | V22: =V15 -> 0.38979447 | W22: =V21 -> 0.35768436 | X22: =V22-W22 -> 0.032110116
B23: C03757 | C23: 44934 | L23: C00266 | M23: 1 | N23: 1 | R23: 4 | S23: 2026 | T23: =T16 -> 68 | U23: =U16 -> 12 | V23: =V16 -> 0.17647059 | W23: =V22 -> 0.38979447 | X23: =V23-W23 -> -0.21332388
B24: C03307 | C24: 44935 | L24: C00270 | M24: 1 | N24: 1
B25: C00547 | C25: 44936 | L25: C00318 | M25: 1 | N25: 1 | S25: Year
B26: C00791 | C26: 44936 | L26: C00319 | M26: 1 | N26: 1 | S26: 2025
B27: C00971 | C27: 44936 | L27: C00353 | M27: 1 | N27: 1
B28: C01301 | C28: 44936 | L28: C00375 | M28: 1 | N28: 1
B29: C03054 | C29: 44936 | L29: C00383 | M29: 1 | N29: 1
B30: C02757 | C30: 44937 | L30: C00420 | M30: 3 | N30: 3
B31: C00197 | C31: 44938 | L31: C00423 | M31: 1 | N31: 1 | P31: Pstn | R31: PY | S31: Year | T31: total_customers | U31: repeated_purchases | V31: repeat_purchase_rate | W31: Previous Year Rate | X31: YoY Variance
B32: C01932 | C32: 44938 | L32: C00435 | M32: 10 | N32: 10 | P32: =MATCH($S$26,$S$20:$S$23,0)-1 -> 2 | R32: {=IF(S32=2023, "", INDEX($S$20:$S$23,$P$32,1))} -> 2024 | S32: =S26 -> 2025 | T32: =VLOOKUP($S$32,$S$20:$X$23,2,0) -> 1411 | U32: =VLOOKUP($S$32,$S$20:$X$23,3,0) -> 550 | V32: =VLOOKUP($S$32,$S$20:$X$23,4,0) -> 0.38979447 | W32: =VLOOKUP($S$32,$S$20:$X$23,5,0) -> 0.35768436 | X32: =VLOOKUP($S$32,$S$20:$X$23,6,0) -> 0.032110116
B33: C02016 | C33: 44938 | L33: C00437 | M33: 1 | N33: 1
B34: C03467 | C34: 44938 | L34: C00444 | M34: 2 | N34: 2
B35: C02384 | C35: 44939 | L35: C00451 | M35: 4 | N35: 4
B36: C02477 | C36: 44940 | L36: C00457 | M36: 1 | N36: 1
B37: C03751 | C37: 44942 | L37: C00458 | M37: 1 | N37: 1
B38: C03650 | C38: 44945 | L38: C00462 | M38: 1 | N38: 1
B39: C02801 | C39: 44946 | L39: C00478 | M39: 1 | N39: 1
B40: C03731 | C40: 44946 | L40: C00481 | M40: 2 | N40: 2
B41: C03340 | C41: 44946 | L41: C00490 | M41: 1 | N41: 1
B42: C01429 | C42: 44947 | L42: C00510 | M42: 1 | N42: 1
B43: C01251 | C43: 44948 | L43: C00559 | M43: 1 | N43: 1
B44: C02752 | C44: 44950 | L44: C00576 | M44: 1 | N44: 1
...

Sheet Cust-Pro-Pivots
B2: product_name | C2: Gross Revenue | E2: product_name | F2: Orders | H2: category | I2: Revenue | K2: product_name | L2: net_revenue | M2: % Contribution | O2: customer_id | P2: net_revenue | Q2: % Contribution | S2: region | T2: net_revenue | U2: % Contribution | W2: returned | X2: gross_revenue | Z2: age_group | AA2: net_revenue | AD2: product_name | AE2: total_orders | AF2: returned_orders | AG2: %_orders_returned | AI2: region | AJ2: product_name | AK2: gross_revenue | AL2: returned_revenue | AM2: net_revenue | AN2: total_orders | AO2: returned_orders | AP2: %_orders_returned
B3: Building Blocks | C3: 41560.09 | E3: Building Blocks | F3: 347 | H3: Electronics | I3: 7908247.2 | K3: Smart TV | L3: 80020.14 | M3: 0.27239164 | O3: C02803 | P3: 15360.1 | Q3: 0.047513501 | S3: Europe | T3: 763029.53 | U3: 0.22728472 | W3: No | X3: 3344695.8 | Z3: Youth Age [>18] | AA3: 201803.76 | AD3: Yoga Mat | AE3: 497 | AF3: 46 | AG3: 0.092555332 | AI3: Africa | AJ3: Building Blocks | AK3: 7532.19 | AL3: 606.97 | AM3: 6925.22 | AN3: 61 | AO3: 4 | AP3: 0.06557377
B4: Coffee Beans | C4: 71501 | E4: Coffee Beans | F4: 1187 | H4: Home | I4: 983807.04 | K4: Laptop | L4: 72071.11 | M4: 0.22989524 | O4: C01761 | P4: 13709.73 | Q4: 0.0424084 | S4: Asia | T4: 678777.26 | U4: 0.20284292 | W4: Yes | X4: 267100.71 | Z4: Medium Age [>45] | AA4: 56793.41 | AD4: Sneakers | AE4: 1063 | AF4: 96 | AG4: 0.090310442 | AJ4: Coffee Beans | AK4: 13978.84 | AL4: 1124.47 | AM4: 12854.37 | AN4: 235 | AO4: 19 | AP4: 0.080851064
B5: Coffee Maker | C5: 269460.03 | E5: Coffee Maker | F5: 1128 | H5: Fashion | I5: 932707.73 | K5: Smartphone | L5: 65824.08 | M5: 0.22038443 | O5: C00435 | P5: 13470.73 | Q5: 0.042802364 | S5: South America | T5: 647846.92 | U5: 0.19647718 | W5: Grand Total | X5: 3611796.5 | Z5: Young Age | AA5: 40840.25 | AD5: Laptop | AE5: 1053 | AF5: 93 | AG5: 0.088319088 | AJ5: Coffee Maker | AK5: 54225.29 | AL5: 6123.5 | AM5: 48101.79 | AN5: 239 | AO5: 27 | AP5: 0.11297071
B6: Dumbbells | C6: 103284.14 | E6: Dumbbells | F6: 532 | H6: Beauty | I6: 337095.39 | K6: Vacuum Cleaner | L6: 13981.79 | M6: 0.048343404 | O6: C00607 | P6: 12446.95 | Q6: 0.039220377 | S6: North America | T6: 646104.38 | U6: 0.192556 | Z6: Old Age [>65] | AA6: 2067.87 | AD6: Coffee Maker | AE6: 1128 | AF6: 93 | AG6: 0.082446809 | AJ6: Dumbbells | AK6: 16235.19 | AL6: 1576.11 | AM6: 14659.08 | AN6: 90 | AO6: 9 | AP6: 0.1
B7: Jacket | C7: 423443.77 | E7: Jacket | F7: 1095 | H7: Grocery | I7: 162966.22 | K7: Jacket | L7: 12888.08 | M7: 0.042696697 | O7: C01402 | P7: 11739.55 | Q7: 0.043327979 | S7: Africa | T7: 608937.66 | U7: 0.18083919 | W7: ="Returned Vs Not Rerurned Revenue: " & Z45 -> Returned Vs Not Rerurned Revenue: 2025 | Z7: Grand Total | AA7: 301505.29 | AD7: Coffee Beans | AE7: 1187 | AF7: 96 | AG7: 0.080876158 | AJ7: Jacket | AK7: 80894.42 | AL7: 3569.75 | AM7: 77324.67 | AN7: 208 | AO7: 9 | AP7: 0.043269231
B8: Jeans | C8: 171948.13 | E8: Jeans | F8: 1061 | H8: Sports | I8: 147166.48 | K8: Sneakers | L8: 12014.15 | M8: 0.041132721 | O8: C02398 | P8: 10311.56 | Q8: 0.036188534 | S8: Grand Total | T8: 3344695.8 | U8: 1 | AD8: Dumbbells | AE8: 532 | AF8: 43 | AG8: 0.080827068 | AJ8: Jeans | AK8: 38055.99 | AL8: 2991.32 | AM8: 35064.67 | AN8: 225 | AO8: 20 | AP8: 0.088888889
B9: Laptop | C9: 3168051.2 | E9: Laptop | F9: 1053 | H9: Toys | I9: 126138.21 | K9: Perfume | L9: 8341.55 | M9: 0.026997825 | O9: C00208 | P9: 5353.43 | Q9: 0.016559801 | W9: Returned | X9: Revenue | Y9: % Contribution | Z9: Age Group | AA9: Net Revenue | AD9: Vacuum Cleaner | AE9: 1115 | AF9: 86 | AG9: 0.077130045 | AJ9: Laptop | AK9: 549097.04 | AL9: 38958.61 | AM9: 510138.43 | AN9: 189 | AO9: 17 | AP9: 0.08994709
B10: Organic Snacks Pack | C10: 91465.22 | E10: Organic Snacks Pack | F10: 1161 | H10: Grand Total | I10: 10598128 | K10: Wireless Earbuds | L10: 8115 | M10: 0.026390206 | O10: C00189 | P10: 5152.75 | Q10: 0.015939036 | W10: Not Returned | X10: =X3 -> 3344695.8 | Y10: =X10/$X$12 -> 0.92604768 | Z10: =Z3 -> Youth Age [>18] | AA10: =AA3 -> 201803.76 | AD10: Jacket | AE10: 1095 | AF10: 83 | AG10: 0.075799087 | AJ10: Organic Snacks Pack | AK10: 17387.85 | AL10: 828.41 | AM10: 16559.44 | AN10: 217 | AO10: 11 | AP10: 0.050691244
B11: Perfume | C11: 188198.07 | E11: Perfume | F11: 633 | K11: Coffee Maker | L11: 7021.19 | M11: 0.022959327 | O11: C01440 | P11: 5037.16 | Q11: 0.015581481 | W11: Returned | X11: =X4 -> 267100.71 | Y11: =X11/$X$12 -> 0.073952315 | Z11: =Z4 -> Medium Age [>45] | AA11: =AA4 -> 56793.41 | AD11: Smart TV | AE11: 997 | AF11: 74 | AG11: 0.074222668 | AJ11: Perfume | AK11: 36003.45 | AL11: 2625.25 | AM11: 33378.2 | AN11: 120 | AO11: 9 | AP11: 0.075
B12: Remote Control Car | C12: 84578.12 | E12: Remote Control Car | F12: 377 | H12: Category | I12: Net Revenue | K12: Skin Care Set | L12: 5419.78 | M12: 0.017791185 | O12: C03600 | P12: 4568.9 | Q12: 0.014133009 | X12: =SUM(X10:X11) -> 3611796.5 | Z12: =Z5 -> Young Age | AA12: =AA5 -> 40840.25 | AD12: Jeans | AE12: 1061 | AF12: 76 | AG12: 0.071630537 | AJ12: Remote Control Car | AK12: 18837.74 | AL12: 1274.61 | AM12: 17563.13 | AN12: 81 | AO12: 5 | AP12: 0.061728395
B13: Skin Care Set | C13: 148897.32 | E13: Skin Care Set | F13: 646 | H13: Beauty | I13: =I3 -> 7908247.2 | K13: Jeans | L13: 4240.49 | M13: 0.014180182 | O13: C00420 | P13: 4459.45 | Q13: 0.013794447 | Z13: =Z6 -> Old Age [>65] | AA13: =AA6 -> 2067.87 | AD13: Skin Care Set | AE13: 646 | AF13: 46 | AG13: 0.07120743 | AJ13: Skin Care Set | AK13: 28346.28 | AL13: 2807.69 | AM13: 25538.59 | AN13: 122 | AO13: 9 | AP13: 0.073770492
B14: Smart TV | C14: 2533245.4 | E14: Smart TV | F14: 997 | H14: Electronics | I14: =I4 -> 983807.04 | K14: Dumbbells | L14: 3217.4 | M14: 0.0099524051 | O14: C00948 | P14: 4372 | Q14: 0.013523937 | AD14: Smartphone | AE14: 1051 | AF14: 74 | AG14: 0.070409134 | AJ14: Smart TV | AK14: 504937.35 | AL14: 43179.9 | AM14: 461757.45 | AN14: 198 | AO14: 18 | AP14: 0.090909091
B15: Smartphone | C15: 1848222.8 | E15: Smartphone | F15: 1051 | H15: Fashion | I15: =I5 -> 932707.73 | K15: Remote Control Car | L15: 2074.64 | M15: 0.0066788823 | O15: C00942 | P15: 4353.64 | Q15: 0.013467144 | Z15: ="Net Revenue per Age Group: " &Z45 -> Net Revenue per Age Group: 2025 | AD15: Wireless Earbuds | AE15: 1057 | AF15: 73 | AG15: 0.069063387 | AJ15: Smartphone | AK15: 406086.04 | AL15: 20618.92 | AM15: 385467.12 | AN15: 223 | AO15: 14 | AP15: 0.062780269
B16: Sneakers | C16: 337315.83 | E16: Sneakers | F16: 1063 | H16: Grocery | I16: =I6 -> 337095.39 | K16: Organic Snacks Pack | L16: 1994.73 | M16: 0.0062960547 | O16: C01840 | P16: 4277.44 | Q16: 0.013231434 | AD16: Remote Control Car | AE16: 377 | AF16: 26 | AG16: 0.068965517 | AJ16: Sneakers | AK16: 60067.71 | AL16: 3608.38 | AM16: 56459.33 | AN16: 187 | AO16: 11 | AP16: 0.058823529
B17: Vacuum Cleaner | C17: 714347.01 | E17: Vacuum Cleaner | F17: 1115 | H17: Home | I17: =I7 -> 162966.22 | K17: Coffee Beans | L17: 1752.12 | M17: 0.0056286738 | O17: C01486 | P17: 3941.26 | Q17: 0.012191526 | AD17: Perfume | AE17: 633 | AF17: 41 | AG17: 0.064770932 | AJ17: Vacuum Cleaner | AK17: 145545.66 | AL17: 11166.04 | AM17: 134379.62 | AN17: 225 | AO17: 16 | AP17: 0.071111111
B18: Wireless Earbuds | C18: 358727.71 | E18: Wireless Earbuds | F18: 1057 | H18: Sports | I18: =I8 -> 147166.48 | K18: Building Blocks | L18: 1528.35 | M18: 0.0047276554 | O18: C02812 | P18: 3928.85 | Q18: 0.012153138 | S18: ="Top 10 Customers - Net Revenue(CLT) in the Year: "&Z45 -> Top 10 Customers - Net Revenue(CLT) in the Year: 2025 | AD18: Building Blocks | AE18: 347 | AF18: 22 | AG18: 0.063400576 | AJ18: Wireless Earbuds | AK18: 72311.46 | AL18: 5147.02 | AM18: 67164.44 | AN18: 217 | AO18: 16 | AP18: 0.073732719
B19: Yoga Mat | C19: 43882.34 | E19: Yoga Mat | F19: 497 | H19: Toys | I19: =I9 -> 126138.21 | K19: Yoga Mat | L19: 1000.69 | M19: 0.0035534671 | O19: C02193 | P19: 3901.04 | Q19: 0.012067113 | AD19: Organic Snacks Pack | AE19: 1161 | AF19: 73 | AG19: 0.06287683 | AJ19: Yoga Mat | AK19: 7528.43 | AL19: 716.77 | AM19: 6811.66 | AN19: 89 | AO19: 10 | AP19: 0.11235955
B20: Grand Total | C20: 10598128 | E20: Grand Total | F20: 15000 | K20: Grand Total | L20: 301505.29 | M20: 1 | O20: C02182 | P20: 3895.49 | Q20: 0.012049946 | S20: Customer_id | T20: Net Revenue | U20: % Contribution | W20: net_revenue | X20: Year | AD20: Grand Total | AE20: 15000 | AF20: 1141 | AG20: 0.076066667 | AI20: Africa Total | AK20: 2057070.9 | AL20: 146923.72 | AM20: 1910147.2 | AN20: 2926 | AO20: 224 | AP20: 0.076555024
O21: C01170 | P21: 3828.58 | Q21: 0.012658863 | S21: =O3 -> C02803 | T21: =P3 -> 15360.1 | U21: =Q3 -> 0.047513501 | W21: region | X21: 2023 | Y21: 2024 | Z21: 2025 | AI21: Asia | AJ21: Building Blocks | AK21: 9468.01 | AL21: 624.13 | AM21: 8843.88 | AN21: 81 | AO21: 4 | AP21: 0.049382716
K22: Product Name | L22: Net Revenue | M22: % Contribution | O22: C02614 | P22: 3797.73 | Q22: 0.011747544 | S22: =O4 -> C01761 | T22: =P4 -> 13709.73 | U22: =Q4 -> 0.0424084 | W22: Africa | X22: 62835.82 | Y22: 46035.34 | Z22: 54321.13 | AJ22: Coffee Beans | AK22: 14753.23 | AL22: 1065.16 | AM22: 13688.07 | AN22: 241 | AO22: 18 | AP22: 0.074688797
B23: category | C23: %_orders_returned | K23: =K3 -> Smart TV | L23: =L3 -> 80020.14 | M23: =M3 -> 0.27239164 | O23: C03192 | P23: 3751.84 | Q23: 0.011605592 | S23: =O5 -> C00435 | T23: =P5 -> 13470.73 | U23: =Q5 -> 0.042802364 | W23: Asia | X23: 53635.88 | Y23: 58823.62 | Z23: 52036.34 | AJ23: Coffee Maker | AK23: 54807.08 | AL23: 3746.05 | AM23: 51061.03 | AN23: 230 | AO23: 16 | AP23: 0.069565217
B24: Fashion | C24: 0.08411215 | K24: =K4 -> Laptop | L24: =L4 -> 72071.11 | M24: =M4 -> 0.22989524 | O24: C03318 | P24: 3672.49 | Q24: 0.011360138 | S24: =O6 -> C00607 | T24: =P6 -> 12446.95 | U24: =Q6 -> 0.039220377 | W24: Europe | X24: 47593.2 | Y24: 44982.15 | Z24: 71041.4 | AJ24: Dumbbells | AK24: 22678.43 | AL24: 1518.94 | AM24: 21159.49 | AN24: 112 | AO24: 7 | AP24: 0.0625
B25: Electronics | C25: 0.081967213 | K25: =K5 -> Smartphone | L25: =L5 -> 65824.08 | M25: =M5 -> 0.22038443 | O25: C03243 | P25: 3582.45 | Q25: 0.011081617 | S25: =O7 -> C01402 | T25: =P7 -> 11739.55 | U25: =Q7 -> 0.043327979 | W25: North America | X25: 71015.69 | Y25: 43097.37 | Z25: 68633.1 | AJ25: Jacket | AK25: 84625.07 | AL25: 4642.7 | AM25: 79982.37 | AN25: 215 | AO25: 14 | AP25: 0.065116279
B26: Home | C26: 0.068965517 | K26: =K6 -> Vacuum Cleaner | L26: =L6 -> 13981.79 | M26: =M6 -> 0.048343404 | O26: C02793 | P26: 3514.41 | Q26: 0.010871148 | S26: =O8 -> C02398 | T26: =P8 -> 10311.56 | U26: =Q8 -> 0.036188534 | W26: South America | X26: 52220.43 | Y26: 48948.18 | Z26: 55473.32 | AJ26: Jeans | AK26: 32473.53 | AL26: 1508.77 | AM26: 30964.76 | AN26: 198 | AO26: 9 | AP26: 0.045454545
B27: Sports | C27: 0.064516129 | K27: =K7 -> Jacket | L27: =L7 -> 12888.08 | M27: =M7 -> 0.042696697 | O27: C01559 | P27: 3450.51 | Q27: 0.010673486 | S27: =O9 -> C00208 | T27: =P9 -> 5353.43 | U27: =Q9 -> 0.016559801 | AJ27: Laptop | AK27: 703651.99 | AL27: 50923.81 | AM27: 652728.18 | AN27: 224 | AO27: 17 | AP27: 0.075892857
B28: Beauty | C28: 0.06122449 | K28: =K8 -> Sneakers | L28: =L8 -> 12014.15 | M28: =M8 -> 0.041132721 | O28: C01505 | P28: 3303.24 | Q28: 0.010217935 | S28: =O10 -> C00189 | T28: =P10 -> 5152.75 | U28: =Q10 -> 0.015939036 | AJ28: Organic Snacks Pack | AK28: 17225.11 | AL28: 987.92 | AM28: 16237.19 | AN28: 218 | AO28: 13 | AP28: 0.059633028
B29: Toys | C29: 0.041666667 | K29: =K9 -> Perfume | L29: =L9 -> 8341.55 | M29: =M9 -> 0.026997825 | O29: C00444 | P29: 3287.81 | Q29: 0.010170205 | S29: =O11 -> C01440 | T29: =P11 -> 5037.16 | U29: =Q11 -> 0.015581481 | Y29: =X21 -> 2023 | Z29: =Y21 -> 2024 | AA29: =Z21 -> 2025 | AB29: =AA21 -> 0 | AJ29: Perfume | AK29: 35880.27 | AL29: 2319.15 | AM29: 33561.12 | AN29: 118 | AO29: 8 | AP29: 0.06779661
B30: Grocery | C30: 0.035087719 | K30: =K10 -> Wireless Earbuds | L30: =L10 -> 8115 | M30: =M10 -> 0.026390206 | O30: C01908 | P30: 3264.3 | Q30: 0.010097481 | S30: =O12 -> C03600 | T30: =P12 -> 4568.9 | U30: =Q12 -> 0.014133009 | X30: =W22 -> Africa | Y30: =X22 -> 62835.82 | Z30: =Y22 -> 46035.34 | AA30: =Z22 -> 54321.13 | AB30: =AA22 -> 0 | AJ30: Remote Control Car | AK30: 16300.11 | AL30: 1223.11 | AM30: 15077 | AN30: 70 | AO30: 5 | AP30: 0.071428571
B31: Grand Total | C31: 0.069196429 | K31: =K11 -> Coffee Maker | L31: =L11 -> 7021.19 | M31: =M11 -> 0.022959327 | O31: C01332 | P31: 3200.73 | Q31: 0.0099008397 | X31: =W23 -> Asia | Y31: =X23 -> 53635.88 | Z31: =Y23 -> 58823.62 | AA31: =Z23 -> 52036.34 | AB31: =AA23 -> 0 | AJ31: Skin Care Set | AK31: 32426.49 | AL31: 1840.32 | AM31: 30586.17 | AN31: 140 | AO31: 9 | AP31: 0.064285714
K32: =K12 -> Skin Care Set | L32: =L12 -> 5419.78 | M32: =M12 -> 0.017791185 | O32: C03794 | P32: 2996.33 | Q32: 0.0092685678 | X32: =W24 -> Europe | Y32: =X24 -> 47593.2 | Z32: =Y24 -> 44982.15 | AA32: =Z24 -> 71041.4 | AB32: =AA24 -> 0 | AJ32: Smart TV | AK32: 502218.66 | AL32: 42366.05 | AM32: 459852.61 | AN32: 197 | AO32: 18 | AP32: 0.091370558
B33: ="% Returned Revenue of each Category: " &Z45 -> % Returned Revenue of each Category: 2025 | K33: =K13 -> Jeans | L33: =L13 -> 4240.49 | M33: =M13 -> 0.014180182 | O33: C01971 | P33: 2960.41 | Q33: 0.0091574562 | X33: =W25 -> North America | Y33: =X25 -> 71015.69 | Z33: =Y25 -> 43097.37 | AA33: =Z25 -> 68633.1 | AB33: =AA25 -> 0 | AJ33: Smartphone | AK33: 344052.5 | AL33: 24179.12 | AM33: 319873.38 | AN33: 195 | AO33: 14 | AP33: 0.071794872
B34: Category | C34: % Orders Returned | K34: =K14 -> Dumbbells | L34: =L14 -> 3217.4 | M34: =M14 -> 0.0099524051 | O34: C02385 | P34: 2918.39 | Q34: 0.0090274755 | X34: =W26 -> South America | Y34: =X26 -> 52220.43 | Z34: =Y26 -> 48948.18 | AA34: =Z26 -> 55473.32 | AB34: =AA26 -> 0 | AJ34: Sneakers | AK34: 72328.4 | AL34: 6371.29 | AM34: 65957.11 | AN34: 222 | AO34: 18 | AP34: 0.081081081
B35: =B24 -> Fashion | C35: =C24 -> 0.08411215 | K35: =K15 -> Remote Control Car | L35: =L15 -> 2074.64 | M35: =M15 -> 0.0066788823 | O35: C01609 | P35: 2817.28 | Q35: 0.0087147112 | AJ35: Vacuum Cleaner | AK35: 129044.17 | AL35: 11233.31 | AM35: 117810.86 | AN35: 210 | AO35: 20 | AP35: 0.095238095
B36: =B25 -> Electronics | C36: =C25 -> 0.081967213 | K36: =K16 -> Organic Snacks Pack | L36: =L16 -> 1994.73 | M36: =M16 -> 0.0062960547 | O36: C02065 | P36: 2787.02 | Q36: 0.0086211078 | AA36: =Z45 -> 2025 | AC36: ="Net Revenue by Region in the Year: "&AA36 -> Net Revenue by Region in the Year: 2025 | AJ36: Wireless Earbuds | AK36: 61289.44 | AL36: 1958.84 | AM36: 59330.6 | AN36: 191 | AO36: 6 | AP36: 0.031413613
B37: =B26 -> Home | C37: =C26 -> 0.068965517 | K37: =K17 -> Coffee Beans | L37: =L17 -> 1752.12 | M37: =M17 -> 0.0056286738 | O37: C01920 | P37: 2752.44 | Q37: 0.0085141412 | X37: 2024 | Z37: =X30 -> Africa | AA37: =INDEX($Y$30:$AB$34,MATCH(Z37,$X$30:$X$34,0),MATCH(AA$36,$Y$29:$AB$29,0)) -> 54321.13 | AJ37: Yoga Mat | AK37: 8470.26 | AL37: 733.41 | AM37: 7736.85 | AN37: 92 | AO37: 8 | AP37: 0.086956522
B38: =B27 -> Sports | C38: =C27 -> 0.064516129 | K38: =K18 -> Building Blocks | L38: =L18 -> 1528.35 | M38: =M18 -> 0.0047276554 | O38: C00266 | P38: 2689.87 | Q38: 0.008320593 | Z38: =X31 -> Asia | AA38: =INDEX($Y$30:$AB$34,MATCH(Z38,$X$30:$X$34,0),MATCH(AA$36,$Y$29:$AB$29,0)) -> 52036.34 | AI38: Asia Total | AK38: 2141692.8 | AL38: 157242.08 | AM38: 1984450.7 | AN38: 2954 | AO38: 204 | AP38: 0.069058903
B39: =B28 -> Beauty | C39: =C28 -> 0.06122449 | K39: =K19 -> Yoga Mat | L39: =L19 -> 1000.69 | M39: =M19 -> 0.0035534671 | O39: C00898 | P39: 2632.75 | Q39: 0.0081439034 | Z39: =X32 -> Europe | AA39: =INDEX($Y$30:$AB$34,MATCH(Z39,$X$30:$X$34,0),MATCH(AA$36,$Y$29:$AB$29,0)) -> 71041.4 | AI39: Europe | AJ39: Building Blocks | AK39: 10494.65 | AL39: 501.63 | AM39: 9993.02 | AN39: 85 | AO39: 4 | AP39: 0.047058824
B40: =B29 -> Toys | C40: =C29 -> 0.041666667 | O40: C00789 | P40: 2594.76 | Q40: 0.0093416317 | Z40: =X33 -> North America | AA40: =INDEX($Y$30:$AB$34,MATCH(Z40,$X$30:$X$34,0),MATCH(AA$36,$Y$29:$AB$29,0)) -> 68633.1 | AJ40: Coffee Beans | AK40: 14894.8 | AL40: 1019.52 | AM40: 13875.28 | AN40: 242 | AO40: 18 | AP40: 0.074380165
B41: =B30 -> Grocery | C41: =C30 -> 0.035087719 | K41: ="Net Revenue per Product in the Year: "&Z45 -> Net Revenue per Product in the Year: 2025 | O41: C02219 | P41: 2515.17 | Q41: 0.0077801923 | Z41: =X34 -> South America | AA41: =INDEX($Y$30:$AB$34,MATCH(Z41,$X$30:$X$34,0),MATCH(AA$36,$Y$29:$AB$29,0)) -> 55473.32 | AJ41: Coffee Maker | AK41: 55960.74 | AL41: 2580.2 | AM41: 53380.54 | AN41: 228 | AO41: 12 | AP41: 0.052631579
...

Sheet Orders Returned
C3: region | D3: product_name | E3: gross_revenue | F3: returned_revenue | G3: net_revenue | H3: total_orders | I3: returned_orders | J3: %_orders_returned
C4: Africa | D4: Building Blocks | E4: 7532.19 | F4: 606.97 | G4: 6925.22 | H4: 61 | I4: 4 | J4: 0.06557377
D5: Coffee Beans | E5: 13978.84 | F5: 1124.47 | G5: 12854.37 | H5: 235 | I5: 19 | J5: 0.080851064
D6: Coffee Maker | E6: 54225.29 | F6: 6123.5 | G6: 48101.79 | H6: 239 | I6: 27 | J6: 0.11297071
D7: Dumbbells | E7: 16235.19 | F7: 1576.11 | G7: 14659.08 | H7: 90 | I7: 9 | J7: 0.1
D8: Jacket | E8: 80894.42 | F8: 3569.75 | G8: 77324.67 | H8: 208 | I8: 9 | J8: 0.043269231
D9: Jeans | E9: 38055.99 | F9: 2991.32 | G9: 35064.67 | H9: 225 | I9: 20 | J9: 0.088888889
D10: Laptop | E10: 549097.04 | F10: 38958.61 | G10: 510138.43 | H10: 189 | I10: 17 | J10: 0.08994709
D11: Organic Snacks Pack | E11: 17387.85 | F11: 828.41 | G11: 16559.44 | H11: 217 | I11: 11 | J11: 0.050691244
D12: Perfume | E12: 36003.45 | F12: 2625.25 | G12: 33378.2 | H12: 120 | I12: 9 | J12: 0.075
D13: Remote Control Car | E13: 18837.74 | F13: 1274.61 | G13: 17563.13 | H13: 81 | I13: 5 | J13: 0.061728395
D14: Skin Care Set | E14: 28346.28 | F14: 2807.69 | G14: 25538.59 | H14: 122 | I14: 9 | J14: 0.073770492
D15: Smart TV | E15: 504937.35 | F15: 43179.9 | G15: 461757.45 | H15: 198 | I15: 18 | J15: 0.090909091
D16: Smartphone | E16: 406086.04 | F16: 20618.92 | G16: 385467.12 | H16: 223 | I16: 14 | J16: 0.062780269
... D20: Yoga Mat | E20: 7528.43 | F20: 716.77 | G20: 6811.66 | H20: 89 | I20: 10 | J20: 0.11235955
C21: Africa Total | E21: 2057070.9 | F21: 146923.72 | G21: 1910147.2 | H21: 2926 | I21: 224 | J21: 0.076555024
C22: Asia | D22: Building Blocks | E22: 9468.01 | F22: 624.13 | G22: 8843.88 | H22: 81 | I22: 4 | J22: 0.049382716
D23: Coffee Beans | E23: 14753.23 | F23: 1065.16 | G23: 13688.07 | H23: 241 | I23: 18 | J23: 0.074688797
D24: Coffee Maker | E24: 54807.08 | F24: 3746.05 | G24: 51061.03 | H24: 230 | I24: 16 | J24: 0.069565217
D25: Dumbbells | E25: 22678.43 | F25: 1518.94 | G25: 21159.49 | H25: 112 | I25: 7 | J25: 0.0625
D26: Jacket | E26: 84625.07 | F26: 4642.7 | G26: 79982.37 | H26: 215 | I26: 14 | J26: 0.065116279
D27: Jeans | E27: 32473.53 | F27: 1508.77 | G27: 30964.76 | H27: 198 | I27: 9 | J27: 0.045454545
D28: Laptop | E28: 703651.99 | F28: 50923.81 | G28: 652728.18 | H28: 224 | I28: 17 | J28: 0.075892857
D29: Organic Snacks Pack | E29: 17225.11 | F29: 987.92 | G29: 16237.19 | H29: 218 | I29: 13 | J29: 0.059633028
D30: Perfume | E30: 35880.27 | F30: 2319.15 | G30: 33561.12 | H30: 118 | I30: 8 | J30: 0.06779661
D31: Remote Control Car | E31: 16300.11 | F31: 1223.11 | G31: 15077 | H31: 70 | I31: 5 | J31: 0.071428571
D32: Skin Care Set | E32: 32426.49 | F32: 1840.32 | G32: 30586.17 | H32: 140 | I32: 9 | J32: 0.064285714
D33: Smart TV | E33: 502218.66 | F33: 42366.05 | G33: 459852.61 | H33: 197 | I33: 18 | J33: 0.091370558
D34: Smartphone | E34: 344052.5 | F34: 24179.12 | G34: 319873.38 | H34: 195 | I34: 14 | J34: 0.071794872
... D38: Yoga Mat | E38: 8470.26 | F38: 733.41 | G38: 7736.85 | H38: 92 | I38: 8 | J38: 0.086956522
C39: Asia Total | E39: 2141692.8 | F39: 157242.08 | G39: 1984450.7 | H39: 2954 | I39: 204 | J39: 0.069058903
C40: Europe | D40: Building Blocks | E40: 10494.65 | F40: 501.63 | G40: 9993.02 | H40: 85 | I40: 4 | J40: 0.047058824
D41: Coffee Beans | E41: 14894.8 | F41: 1019.52 | G41: 13875.28 | H41: 242 | I41: 18 | J41: 0.074380165
D42: Coffee Maker | E42: 55960.74 | F42: 2580.2 | G42: 53380.54 | H42: 228 | I42: 12 | J42: 0.052631579
D43: Dumbbells | E43: 23170.83 | F43: 3042.83 | G43: 20128 | H43: 117 | I43: 14 | J43: 0.11965812
D44: Jacket | E44: 97508.86 | F44: 8645.05 | G44: 88863.81 | H44: 251 | I44: 21 | J44: 0.083665339
D45: Jeans | E45: 33531.52 | F45: 2373.9 | G45: 31157.62 | H45: 212 | I45: 15 | J45: 0.070754717
D46: Laptop | E46: 703382.19 | F46: 47697.62 | G46: 655684.57 | H46: 231 | I46: 18 | J46: 0.077922078
D47: Organic Snacks Pack | E47: 20205.08 | F47: 1729.95 | G47: 18475.13 | H47: 262 | I47: 21 | J47: 0.080152672
D48: Perfume | E48: 42060.85 | F48: 1461.97 | G48: 40598.88 | H48: 142 | I48: 6 | J48: 0.042253521
...

Sheet RFM-Pivot
B2: customer_id | C2: Recency | D2: Frequency | E2: Monetary | G2: Customer ID | H2: Recency | I2: Frequency | J2: Monetary | K2: R-Score | L2: F-Score | M2: M-Score | N2: RFM-Avg | S2: Customer ID | U2: RFM-Avg | V2: Segment | X2: Segment | Y2: Number of Customers | Z2: % Composition
B3: C00002 | C3: 45510 | D3: 2 | E3: 2882.64 | G3: =B3 -> C00002 | H3: =C3 -> 45510 | I3: =D3 -> 2 | J3: =E3 -> 2882.64 | K3: =VLOOKUP(H3,$P$5:$Q$9,2,TRUE) -> 2 | L3: =VLOOKUP(I3,$P$12:$Q$16,2,TRUE) -> 4 | M3: =VLOOKUP(J3,$P$19:$Q$23,2,TRUE) -> 4 | N3: =(K3+L3+M3)/3 -> 3.3333333 | S3: =G3 -> C00002 | T3: =$N3 -> 3.3333333 | U3: =$N3 -> 3.3333333 | V3: =IF(U3>4,"Champions",IF(AND(U3>3,U3<=4),"Loyal or Potential Loyalists",IF(AND(U3>2,U3<=3),"At Risk Customers","Lost Customers"))) -> Loyal or Potential Loyalists | X3: Champions | Y3: =COUNTIF($V$3:$V$2632,X3) -> 574 | Z3: =Y3/($Y$3+$Y$4+$Y$5+$Y$6) -> 0.21825095
B4: C00003 | C4: 45511 | D4: 2 | E4: 5254.16 | G4: =B4 -> C00003 | H4: =C4 -> 45511 | I4: =D4 -> 2 | J4: =E4 -> 5254.16 | K4: =VLOOKUP(H4,$P$5:$Q$9,2,TRUE) -> 2 | L4: =VLOOKUP(I4,$P$12:$Q$16,2,TRUE) -> 4 | M4: =VLOOKUP(J4,$P$19:$Q$23,2,TRUE) -> 5 | N4: =(K4+L4+M4)/3 -> 3.6666667 | P4: Recency | S4: =G4 -> C00003 | T4: =$N4 -> 3.6666667 | U4: =$N4 -> 3.6666667 | V4: =IF(U4>4,"Champions",IF(AND(U4>3,U4<=4),"Loyal or Potential Loyalists",IF(AND(U4>2,U4<=3),"At Risk Customers","Lost Customers"))) -> Loyal or Potential Loyalists | X4: Loyal or Potential Loyalists | Y4: =COUNTIF($V$3:$V$2632,X4) -> 709 | Z4: =Y4/($Y$3+$Y$4+$Y$5+$Y$6) -> 0.26958175
B5: C00009 | C5: 46013 | D5: 2 | E5: 739.92 | G5: =B5 -> C00009 | H5: =C5 -> 46013 | I5: =D5 -> 2 | J5: =E5 -> 739.92 | K5: =VLOOKUP(H5,$P$5:$Q$9,2,TRUE) -> 5 | L5: =VLOOKUP(I5,$P$12:$Q$16,2,TRUE) -> 4 | M5: =VLOOKUP(J5,$P$19:$Q$23,2,TRUE) -> 3 | N5: =(K5+L5+M5)/3 -> 4 | P5: =_xlfn.PERCENTILE.INC($H$3:$H$2632,0) -> 44934 | Q5: 1 | S5: =G5 -> C00009 | T5: =$N5 -> 4 | U5: =$N5 -> 4 | V5: =IF(U5>4,"Champions",IF(AND(U5>3,U5<=4),"Loyal or Potential Loyalists",IF(AND(U5>2,U5<=3),"At Risk Customers","Lost Customers"))) -> Loyal or Potential Loyalists | X5: At Risk Customers | Y5: =COUNTIF($V$3:$V$2632,X5) -> 924 | Z5: =Y5/($Y$3+$Y$4+$Y$5+$Y$6) -> 0.3513308
B6: C00013 | C6: 45970 | D6: 1 | E6: 72.49 | G6: =B6 -> C00013 | H6: =C6 -> 45970 | I6: =D6 -> 1 | J6: =E6 -> 72.49 | K6: =VLOOKUP(H6,$P$5:$Q$9,2,TRUE) -> 5 | L6: =VLOOKUP(I6,$P$12:$Q$16,2,TRUE) -> 3 | M6: =VLOOKUP(J6,$P$19:$Q$23,2,TRUE) -> 1 | N6: =(K6+L6+M6)/3 -> 3 | P6: =_xlfn.PERCENTILE.INC($H$3:$H$2632,0.2) -> 45320.8 | Q6: 2 | S6: =G6 -> C00013 | T6: =$N6 -> 3 | U6: =$N6 -> 3 | V6: =IF(U6>4,"Champions",IF(AND(U6>3,U6<=4),"Loyal or Potential Loyalists",IF(AND(U6>2,U6<=3),"At Risk Customers","Lost Customers"))) -> At Risk Customers | X6: Lost Customers | Y6: =COUNTIF($V$3:$V$2632,X6) -> 423 | Z6: =Y6/($Y$3+$Y$4+$Y$5+$Y$6) -> 0.1608365
B7: C00015 | C7: 46014 | D7: 2 | E7: 4643.38 | G7: =B7 -> C00015 | H7: =C7 -> 46014 | I7: =D7 -> 2 | J7: =E7 -> 4643.38 | K7: =VLOOKUP(H7,$P$5:$Q$9,2,TRUE) -> 5 | L7: =VLOOKUP(I7,$P$12:$Q$16,2,TRUE) -> 4 | M7: =VLOOKUP(J7,$P$19:$Q$23,2,TRUE) -> 5 | N7: =(K7+L7+M7)/3 -> 4.6666667 | P7: =_xlfn.PERCENTILE.INC($H$3:$H$2632,0.4) -> 45594.6 | Q7: 3 | S7: =G7 -> C00015 | T7: =$N7 -> 4.6666667 | U7: =$N7 -> 4.6666667 | V7: =IF(U7>4,"Champions",IF(AND(U7>3,U7<=4),"Loyal or Potential Loyalists",IF(AND(U7>2,U7<=3),"At Risk Customers","Lost Customers"))) -> Champions
B8: C00016 | C8: 45526 | D8: 3 | E8: 420.91 | G8: =B8 -> C00016 | H8: =C8 -> 45526 | I8: =D8 -> 3 | J8: =E8 -> 420.91 | K8: =VLOOKUP(H8,$P$5:$Q$9,2,TRUE) -> 2 | L8: =VLOOKUP(I8,$P$12:$Q$16,2,TRUE) -> 4 | M8: =VLOOKUP(J8,$P$19:$Q$23,2,TRUE) -> 2 | N8: =(K8+L8+M8)/3 -> 2.6666667 | P8: =_xlfn.PERCENTILE.INC($H$3:$H$2632,0.6) -> 45799 | Q8: 4 | S8: =G8 -> C00016 | T8: =$N8 -> 2.6666667 | U8: =$N8 -> 2.6666667 | V8: =IF(U8>4,"Champions",IF(AND(U8>3,U8<=4),"Loyal or Potential Loyalists",IF(AND(U8>2,U8<=3),"At Risk Customers","Lost Customers"))) -> At Risk Customers
B9: C00017 | C9: 45895 | D9: 1 | E9: 491.54 | G9: =B9 -> C00017 | H9: =C9 -> 45895 | I9: =D9 -> 1 | J9: =E9 -> 491.54 | K9: =VLOOKUP(H9,$P$5:$Q$9,2,TRUE) -> 4 | L9: =VLOOKUP(I9,$P$12:$Q$16,2,TRUE) -> 3 | M9: =VLOOKUP(J9,$P$19:$Q$23,2,TRUE) -> 3 | N9: =(K9+L9+M9)/3 -> 3.3333333 | P9: =_xlfn.PERCENTILE.INC($H$3:$H$2632,0.8) -> 45940 | Q9: 5 | S9: =G9 -> C00017 | T9: =$N9 -> 3.3333333 | U9: =$N9 -> 3.3333333 | V9: =IF(U9>4,"Champions",IF(AND(U9>3,U9<=4),"Loyal or Potential Loyalists",IF(AND(U9>2,U9<=3),"At Risk Customers","Lost Customers"))) -> Loyal or Potential Loyalists
B10: C00018 | C10: 45680 | D10: 1 | E10: 40.34 | G10: =B10 -> C00018 | H10: =C10 -> 45680 | I10: =D10 -> 1 | J10: =E10 -> 40.34 | K10: =VLOOKUP(H10,$P$5:$Q$9,2,TRUE) -> 3 | L10: =VLOOKUP(I10,$P$12:$Q$16,2,TRUE) -> 3 | M10: =VLOOKUP(J10,$P$19:$Q$23,2,TRUE) -> 1 | N10: =(K10+L10+M10)/3 -> 2.3333333 | S10: =G10 -> C00018 | T10: =$N10 -> 2.3333333 | U10: =$N10 -> 2.3333333 | V10: =IF(U10>4,"Champions",IF(AND(U10>3,U10<=4),"Loyal or Potential Loyalists",IF(AND(U10>2,U10<=3),"At Risk Customers","Lost Customers"))) -> At Risk Customers
B11: C00019 | C11: 45846 | D11: 2 | E11: 1055.66 | G11: =B11 -> C00019 | H11: =C11 -> 45846 | I11: =D11 -> 2 | J11: =E11 -> 1055.66 | K11: =VLOOKUP(H11,$P$5:$Q$9,2,TRUE) -> 4 | L11: =VLOOKUP(I11,$P$12:$Q$16,2,TRUE) -> 4 | M11: =VLOOKUP(J11,$P$19:$Q$23,2,TRUE) -> 3 | N11: =(K11+L11+M11)/3 -> 3.6666667 | P11: Frequency | S11: =G11 -> C00019 | T11: =$N11 -> 3.6666667 | U11: =$N11 -> 3.6666667 | V11: =IF(U11>4,"Champions",IF(AND(U11>3,U11<=4),"Loyal or Potential Loyalists",IF(AND(U11>2,U11<=3),"At Risk Customers","Lost Customers"))) -> Loyal or Potential Loyalists
B12: C00024 | C12: 45999 | D12: 1 | E12: 2992.11 | G12: =B12 -> C00024 | H12: =C12 -> 45999 | I12: =D12 -> 1 | J12: =E12 -> 2992.11 | K12: =VLOOKUP(H12,$P$5:$Q$9,2,TRUE) -> 5 | L12: =VLOOKUP(I12,$P$12:$Q$16,2,TRUE) -> 3 | M12: =VLOOKUP(J12,$P$19:$Q$23,2,TRUE) -> 4 | N12: =(K12+L12+M12)/3 -> 4 | P12: =_xlfn.PERCENTILE.INC(I3:I2632,0) -> 1 | Q12: 1 | S12: =G12 -> C00024 | T12: =$N12 -> 4 | U12: =$N12 -> 4 | V12: =IF(U12>4,"Champions",IF(AND(U12>3,U12<=4),"Loyal or Potential Loyalists",IF(AND(U12>2,U12<=3),"At Risk Customers","Lost Customers"))) -> Loyal or Potential Loyalists
B13: C00027 | C13: 45668 | D13: 1 | E13: 161 | G13: =B13 -> C00027 | H13: =C13 -> 45668 | I13: =D13 -> 1 | J13: =E13 -> 161 | K13: =VLOOKUP(H13,$P$5:$Q$9,2,TRUE) -> 3 | L13: =VLOOKUP(I13,$P$12:$Q$16,2,TRUE) -> 3 | M13: =VLOOKUP(J13,$P$19:$Q$23,2,TRUE) -> 1 | N13: =(K13+L13+M13)/3 -> 2.3333333 | P13: =_xlfn.PERCENTILE.INC(I4:I2633,0.2) -> 1 | Q13: 2 | S13: =G13 -> C00027 | T13: =$N13 -> 2.3333333 | U13: =$N13 -> 2.3333333 | V13: =IF(U13>4,"Champions",IF(AND(U13>3,U13<=4),"Loyal or Potential Loyalists",IF(AND(U13>2,U13<=3),"At Risk Customers","Lost Customers"))) -> At Risk Customers
B14: C00028 | C14: 45847 | D14: 3 | E14: 777.7 | G14: =B14 -> C00028 | H14: =C14 -> 45847 | I14: =D14 -> 3 | J14: =E14 -> 777.7 | K14: =VLOOKUP(H14,$P$5:$Q$9,2,TRUE) -> 4 | L14: =VLOOKUP(I14,$P$12:$Q$16,2,TRUE) -> 4 | M14: =VLOOKUP(J14,$P$19:$Q$23,2,TRUE) -> 3 | N14: =(K14+L14+M14)/3 -> 3.6666667 | P14: =_xlfn.PERCENTILE.INC(I5:I2634,0.4) -> 1 | Q14: 3 | S14: =G14 -> C00028 | T14: =$N14 -> 3.6666667 | U14: =$N14 -> 3.6666667 | V14: =IF(U14>4,"Champions",IF(AND(U14>3,U14<=4),"Loyal or Potential Loyalists",IF(AND(U14>2,U14<=3),"At Risk Customers","Lost Customers"))) -> Loyal or Potential Loyalists
B15: C00031 | C15: 45974 | D15: 1 | E15: 60.38 | G15: =B15 -> C00031 | H15: =C15 -> 45974 | I15: =D15 -> 1 | J15: =E15 -> 60.38 | K15: =VLOOKUP(H15,$P$5:$Q$9,2,TRUE) -> 5 | L15: =VLOOKUP(I15,$P$12:$Q$16,2,TRUE) -> 3 | M15: =VLOOKUP(J15,$P$19:$Q$23,2,TRUE) -> 1 | N15: =(K15+L15+M15)/3 -> 3 | P15: =_xlfn.PERCENTILE.INC(I6:I2635,0.6) -> 2 | Q15: 4 | S15: =G15 -> C00031 | T15: =$N15 -> 3 | U15: =$N15 -> 3 | V15: =IF(U15>4,"Champions",IF(AND(U15>3,U15<=4),"Loyal or Potential Loyalists",IF(AND(U15>2,U15<=3),"At Risk Customers","Lost Customers"))) -> At Risk Customers
B16: C00032 | C16: 46006 | D16: 5 | E16: 849.31 | G16: =B16 -> C00032 | H16: =C16 -> 46006 | I16: =D16 -> 5 | J16: =E16 -> 849.31 | K16: =VLOOKUP(H16,$P$5:$Q$9,2,TRUE) -> 5 | L16: =VLOOKUP(I16,$P$12:$Q$16,2,TRUE) -> 5 | M16: =VLOOKUP(J16,$P$19:$Q$23,2,TRUE) -> 3 | N16: =(K16+L16+M16)/3 -> 4.3333333 | P16: =_xlfn.PERCENTILE.INC(I7:I2636,0.8) -> 4 | Q16: 5 | S16: =G16 -> C00032 | T16: =$N16 -> 4.3333333 | U16: =$N16 -> 4.3333333 | V16: =IF(U16>4,"Champions",IF(AND(U16>3,U16<=4),"Loyal or Potential Loyalists",IF(AND(U16>2,U16<=3),"At Risk Customers","Lost Customers"))) -> Champions
B17: C00034 | C17: 45760 | D17: 3 | E17: 2767.63 | G17: =B17 -> C00034 | H17: =C17 -> 45760 | I17: =D17 -> 3 | J17: =E17 -> 2767.63 | K17: =VLOOKUP(H17,$P$5:$Q$9,2,TRUE) -> 3 | L17: =VLOOKUP(I17,$P$12:$Q$16,2,TRUE) -> 4 | M17: =VLOOKUP(J17,$P$19:$Q$23,2,TRUE) -> 4 | N17: =(K17+L17+M17)/3 -> 3.6666667 | S17: =G17 -> C00034 | T17: =$N17 -> 3.6666667 | U17: =$N17 -> 3.6666667 | V17: =IF(U17>4,"Champions",IF(AND(U17>3,U17<=4),"Loyal or Potential Loyalists",IF(AND(U17>2,U17<=3),"At Risk Customers","Lost Customers"))) -> Loyal or Potential Loyalists
B18: C00035 | C18: 45480 | D18: 3 | E18: 4302.76 | G18: =B18 -> C00035 | H18: =C18 -> 45480 | I18: =D18 -> 3 | J18: =E18 -> 4302.76 | K18: =VLOOKUP(H18,$P$5:$Q$9,2,TRUE) -> 2 | L18: =VLOOKUP(I18,$P$12:$Q$16,2,TRUE) -> 4 | M18: =VLOOKUP(J18,$P$19:$Q$23,2,TRUE) -> 5 | N18: =(K18+L18+M18)/3 -> 3.6666667 | P18: Monetary | S18: =G18 -> C00035 | T18: =$N18 -> 3.6666667 | U18: =$N18 -> 3.6666667 | V18: =IF(U18>4,"Champions",IF(AND(U18>3,U18<=4),"Loyal or Potential Loyalists",IF(AND(U18>2,U18<=3),"At Risk Customers","Lost Customers"))) -> Loyal or Potential Loyalists
B19: C00036 | C19: 45917 | D19: 1 | E19: 190.72 | G19: =B19 -> C00036 | H19: =C19 -> 45917 | I19: =D19 -> 1 | J19: =E19 -> 190.72 | K19: =VLOOKUP(H19,$P$5:$Q$9,2,TRUE) -> 4 | L19: =VLOOKUP(I19,$P$12:$Q$16,2,TRUE) -> 3 | M19: =VLOOKUP(J19,$P$19:$Q$23,2,TRUE) -> 2 | N19: =(K19+L19+M19)/3 -> 3 | P19: =_xlfn.PERCENTILE.INC($J$3:$J$2632,0) -> 24.27 | Q19: 1 | S19: =G19 -> C00036 | T19: =$N19 -> 3 | U19: =$N19 -> 3 | V19: =IF(U19>4,"Champions",IF(AND(U19>3,U19<=4),"Loyal or Potential Loyalists",IF(AND(U19>2,U19<=3),"At Risk Customers","Lost Customers"))) -> At Risk Customers
B20: C00037 | C20: 45603 | D20: 2 | E20: 510.56 | G20: =B20 -> C00037 | H20: =C20 -> 45603 | I20: =D20 -> 2 | J20: =E20 -> 510.56 | K20: =VLOOKUP(H20,$P$5:$Q$9,2,TRUE) -> 3 | L20: =VLOOKUP(I20,$P$12:$Q$16,2,TRUE) -> 4 | M20: =VLOOKUP(J20,$P$19:$Q$23,2,TRUE) -> 3 | N20: =(K20+L20+M20)/3 -> 3.3333333 | P20: =_xlfn.PERCENTILE.INC($J$3:$J$2632,0.2) -> 187.832 | Q20: 2 | S20: =G20 -> C00037 | T20: =$N20 -> 3.3333333 | U20: =$N20 -> 3.3333333 | V20: =IF(U20>4,"Champions",IF(AND(U20>3,U20<=4),"Loyal or Potential Loyalists",IF(AND(U20>2,U20<=3),"At Risk Customers","Lost Customers"))) -> Loyal or Potential Loyalists
B21: C00038 | C21: 45635 | D21: 1 | E21: 135.67 | G21: =B21 -> C00038 | H21: =C21 -> 45635 | I21: =D21 -> 1 | J21: =E21 -> 135.67 | K21: =VLOOKUP(H21,$P$5:$Q$9,2,TRUE) -> 3 | L21: =VLOOKUP(I21,$P$12:$Q$16,2,TRUE) -> 3 | M21: =VLOOKUP(J21,$P$19:$Q$23,2,TRUE) -> 1 | N21: =(K21+L21+M21)/3 -> 2.3333333 | P21: =_xlfn.PERCENTILE.INC($J$3:$J$2632,0.4) -> 460.064 | Q21: 3 | S21: =G21 -> C00038 | T21: =$N21 -> 2.3333333 | U21: =$N21 -> 2.3333333 | V21: =IF(U21>4,"Champions",IF(AND(U21>3,U21<=4),"Loyal or Potential Loyalists",IF(AND(U21>2,U21<=3),"At Risk Customers","Lost Customers"))) -> At Risk Customers
B22: C00039 | C22: 45035 | D22: 1 | E22: 189.23 | G22: =B22 -> C00039 | H22: =C22 -> 45035 | I22: =D22 -> 1 | J22: =E22 -> 189.23 | K22: =VLOOKUP(H22,$P$5:$Q$9,2,TRUE) -> 1 | L22: =VLOOKUP(I22,$P$12:$Q$16,2,TRUE) -> 3 | M22: =VLOOKUP(J22,$P$19:$Q$23,2,TRUE) -> 2 | N22: =(K22+L22+M22)/3 -> 2 | P22: =_xlfn.PERCENTILE.INC($J$3:$J$2632,0.6) -> 1197.896 | Q22: 4 | S22: =G22 -> C00039 | T22: =$N22 -> 2 | U22: =$N22 -> 2 | V22: =IF(U22>4,"Champions",IF(AND(U22>3,U22<=4),"Loyal or Potential Loyalists",IF(AND(U22>2,U22<=3),"At Risk Customers","Lost Customers"))) -> Lost Customers
B23: C00041 | C23: 45983 | D23: 3 | E23: 244.88 | G23: =B23 -> C00041 | H23: =C23 -> 45983 | I23: =D23 -> 3 | J23: =E23 -> 244.88 | K23: =VLOOKUP(H23,$P$5:$Q$9,2,TRUE) -> 5 | L23: =VLOOKUP(I23,$P$12:$Q$16,2,TRUE) -> 4 | M23: =VLOOKUP(J23,$P$19:$Q$23,2,TRUE) -> 2 | N23: =(K23+L23+M23)/3 -> 3.6666667 | P23: =_xlfn.PERCENTILE.INC($J$3:$J$2632,0.8) -> 3692.102 | Q23: 5 | S23: =G23 -> C00041 | T23: =$N23 -> 3.6666667 | U23: =$N23 -> 3.6666667 | V23: =IF(U23>4,"Champions",IF(AND(U23>3,U23<=4),"Loyal or Potential Loyalists",IF(AND(U23>2,U23<=3),"At Risk Customers","Lost Customers"))) -> Loyal or Potential Loyalists
B24: C00042 | C24: 45956 | D24: 4 | E24: 10415.61 | G24: =B24 -> C00042 | H24: =C24 -> 45956 | I24: =D24 -> 4 | J24: =E24 -> 10415.61 | K24: =VLOOKUP(H24,$P$5:$Q$9,2,TRUE) -> 5 | L24: =VLOOKUP(I24,$P$12:$Q$16,2,TRUE) -> 5 | M24: =VLOOKUP(J24,$P$19:$Q$23,2,TRUE) -> 5 | N24: =(K24+L24+M24)/3 -> 5 | S24: =G24 -> C00042 | T24: =$N24 -> 5 | U24: =$N24 -> 5 | V24: =IF(U24>4,"Champions",IF(AND(U24>3,U24<=4),"Loyal or Potential Loyalists",IF(AND(U24>2,U24<=3),"At Risk Customers","Lost Customers"))) -> Champions
B25: C00043 | C25: 45594 | D25: 1 | E25: 194.59 | G25: =B25 -> C00043 | H25: =C25 -> 45594 | I25: =D25 -> 1 | J25: =E25 -> 194.59 | K25: =VLOOKUP(H25,$P$5:$Q$9,2,TRUE) -> 2 | L25: =VLOOKUP(I25,$P$12:$Q$16,2,TRUE) -> 3 | M25: =VLOOKUP(J25,$P$19:$Q$23,2,TRUE) -> 2 | N25: =(K25+L25+M25)/3 -> 2.3333333 | S25: =G25 -> C00043 | T25: =$N25 -> 2.3333333 | U25: =$N25 -> 2.3333333 | V25: =IF(U25>4,"Champions",IF(AND(U25>3,U25<=4),"Loyal or Potential Loyalists",IF(AND(U25>2,U25<=3),"At Risk Customers","Lost Customers"))) -> At Risk Customers
B26: C00044 | C26: 45551 | D26: 3 | E26: 5535.59 | G26: =B26 -> C00044 | H26: =C26 -> 45551 | I26: =D26 -> 3 | J26: =E26 -> 5535.59 | K26: =VLOOKUP(H26,$P$5:$Q$9,2,TRUE) -> 2 | L26: =VLOOKUP(I26,$P$12:$Q$16,2,TRUE) -> 4 | M26: =VLOOKUP(J26,$P$19:$Q$23,2,TRUE) -> 5 | N26: =(K26+L26+M26)/3 -> 3.6666667 | S26: =G26 -> C00044 | T26: =$N26 -> 3.6666667 | U26: =$N26 -> 3.6666667 | V26: =IF(U26>4,"Champions",IF(AND(U26>3,U26<=4),"Loyal or Potential Loyalists",IF(AND(U26>2,U26<=3),"At Risk Customers","Lost Customers"))) -> Loyal or Potential Loyalists
B27: C00046 | C27: 45637 | D27: 1 | E27: 293.24 | G27: =B27 -> C00046 | H27: =C27 -> 45637 | I27: =D27 -> 1 | J27: =E27 -> 293.24 | K27: =VLOOKUP(H27,$P$5:$Q$9,2,TRUE) -> 3 | L27: =VLOOKUP(I27,$P$12:$Q$16,2,TRUE) -> 3 | M27: =VLOOKUP(J27,$P$19:$Q$23,2,TRUE) -> 2 | N27: =(K27+L27+M27)/3 -> 2.6666667 | S27: =G27 -> C00046 | T27: =$N27 -> 2.6666667 | U27: =$N27 -> 2.6666667 | V27: =IF(U27>4,"Champions",IF(AND(U27>3,U27<=4),"Loyal or Potential Loyalists",IF(AND(U27>2,U27<=3),"At Risk Customers","Lost Customers"))) -> At Risk Customers
B28: C00047 | C28: 45960 | D28: 7 | E28: 6136.17 | G28: =B28 -> C00047 | H28: =C28 -> 45960 | I28: =D28 -> 7 | J28: =E28 -> 6136.17 | K28: =VLOOKUP(H28,$P$5:$Q$9,2,TRUE) -> 5 | L28: =VLOOKUP(I28,$P$12:$Q$16,2,TRUE) -> 5 | M28: =VLOOKUP(J28,$P$19:$Q$23,2,TRUE) -> 5 | N28: =(K28+L28+M28)/3 -> 5 | S28: =G28 -> C00047 | T28: =$N28 -> 5 | U28: =$N28 -> 5 | V28: =IF(U28>4,"Champions",IF(AND(U28>3,U28<=4),"Loyal or Potential Loyalists",IF(AND(U28>2,U28<=3),"At Risk Customers","Lost Customers"))) -> Champions
B29: C00049 | C29: 45182 | D29: 1 | E29: 303.9 | G29: =B29 -> C00049 | H29: =C29 -> 45182 | I29: =D29 -> 1 | J29: =E29 -> 303.9 | K29: =VLOOKUP(H29,$P$5:$Q$9,2,TRUE) -> 1 | L29: =VLOOKUP(I29,$P$12:$Q$16,2,TRUE) -> 3 | M29: =VLOOKUP(J29,$P$19:$Q$23,2,TRUE) -> 2 | N29: =(K29+L29+M29)/3 -> 2 | S29: =G29 -> C00049 | T29: =$N29 -> 2 | U29: =$N29 -> 2 | V29: =IF(U29>4,"Champions",IF(AND(U29>3,U29<=4),"Loyal or Potential Loyalists",IF(AND(U29>2,U29<=3),"At Risk Customers","Lost Customers"))) -> Lost Customers
B30: C00051 | C30: 45957 | D30: 3 | E30: 456.26 | G30: =B30 -> C00051 | H30: =C30 -> 45957 | I30: =D30 -> 3 | J30: =E30 -> 456.26 | K30: =VLOOKUP(H30,$P$5:$Q$9,2,TRUE) -> 5 | L30: =VLOOKUP(I30,$P$12:$Q$16,2,TRUE) -> 4 | M30: =VLOOKUP(J30,$P$19:$Q$23,2,TRUE) -> 2 | N30: =(K30+L30+M30)/3 -> 3.6666667 | S30: =G30 -> C00051 | T30: =$N30 -> 3.6666667 | U30: =$N30 -> 3.6666667 | V30: =IF(U30>4,"Champions",IF(AND(U30>3,U30<=4),"Loyal or Potential Loyalists",IF(AND(U30>2,U30<=3),"At Risk Customers","Lost Customers"))) -> Loyal or Potential Loyalists
B31: C00052 | C31: 45949 | D31: 6 | E31: 10516.7 | G31: =B31 -> C00052 | H31: =C31 -> 45949 | I31: =D31 -> 6 | J31: =E31 -> 10516.7 | K31: =VLOOKUP(H31,$P$5:$Q$9,2,TRUE) -> 5 | L31: =VLOOKUP(I31,$P$12:$Q$16,2,TRUE) -> 5 | M31: =VLOOKUP(J31,$P$19:$Q$23,2,TRUE) -> 5 | N31: =(K31+L31+M31)/3 -> 5 | S31: =G31 -> C00052 | T31: =$N31 -> 5 | U31: =$N31 -> 5 | V31: =IF(U31>4,"Champions",IF(AND(U31>3,U31<=4),"Loyal or Potential Loyalists",IF(AND(U31>2,U31<=3),"At Risk Customers","Lost Customers"))) -> Champions
B32: C00054 | C32: 45470 | D32: 1 | E32: 1117.35 | G32: =B32 -> C00054 | H32: =C32 -> 45470 | I32: =D32 -> 1 | J32: =E32 -> 1117.35 | K32: =VLOOKUP(H32,$P$5:$Q$9,2,TRUE) -> 2 | L32: =VLOOKUP(I32,$P$12:$Q$16,2,TRUE) -> 3 | M32: =VLOOKUP(J32,$P$19:$Q$23,2,TRUE) -> 3 | N32: =(K32+L32+M32)/3 -> 2.6666667 | S32: =G32 -> C00054 | T32: =$N32 -> 2.6666667 | U32: =$N32 -> 2.6666667 | V32: =IF(U32>4,"Champions",IF(AND(U32>3,U32<=4),"Loyal or Potential Loyalists",IF(AND(U32>2,U32<=3),"At Risk Customers","Lost Customers"))) -> At Risk Customers
B33: C00055 | C33: 45314 | D33: 2 | E33: 2632.08 | G33: =B33 -> C00055 | H33: =C33 -> 45314 | I33: =D33 -> 2 | J33: =E33 -> 2632.08 | K33: =VLOOKUP(H33,$P$5:$Q$9,2,TRUE) -> 1 | L33: =VLOOKUP(I33,$P$12:$Q$16,2,TRUE) -> 4 | M33: =VLOOKUP(J33,$P$19:$Q$23,2,TRUE) -> 4 | N33: =(K33+L33+M33)/3 -> 3 | S33: =G33 -> C00055 | T33: =$N33 -> 3 | U33: =$N33 -> 3 | V33: =IF(U33>4,"Champions",IF(AND(U33>3,U33<=4),"Loyal or Potential Loyalists",IF(AND(U33>2,U33<=3),"At Risk Customers","Lost Customers"))) -> At Risk Customers
B34: C00056 | C34: 45453 | D34: 1 | E34: 486.51 | G34: =B34 -> C00056 | H34: =C34 -> 45453 | I34: =D34 -> 1 | J34: =E34 -> 486.51 | K34: =VLOOKUP(H34,$P$5:$Q$9,2,TRUE) -> 2 | L34: =VLOOKUP(I34,$P$12:$Q$16,2,TRUE) -> 3 | M34: =VLOOKUP(J34,$P$19:$Q$23,2,TRUE) -> 3 | N34: =(K34+L34+M34)/3 -> 2.6666667 | S34: =G34 -> C00056 | T34: =$N34 -> 2.6666667 | U34: =$N34 -> 2.6666667 | V34: =IF(U34>4,"Champions",IF(AND(U34>3,U34<=4),"Loyal or Potential Loyalists",IF(AND(U34>2,U34<=3),"At Risk Customers","Lost Customers"))) -> At Risk Customers
B35: C00057 | C35: 45544 | D35: 2 | E35: 2731.82 | G35: =B35 -> C00057 | H35: =C35 -> 45544 | I35: =D35 -> 2 | J35: =E35 -> 2731.82 | K35: =VLOOKUP(H35,$P$5:$Q$9,2,TRUE) -> 2 | L35: =VLOOKUP(I35,$P$12:$Q$16,2,TRUE) -> 4 | M35: =VLOOKUP(J35,$P$19:$Q$23,2,TRUE) -> 4 | N35: =(K35+L35+M35)/3 -> 3.3333333 | S35: =G35 -> C00057 | T35: =$N35 -> 3.3333333 | U35: =$N35 -> 3.3333333 | V35: =IF(U35>4,"Champions",IF(AND(U35>3,U35<=4),"Loyal or Potential Loyalists",IF(AND(U35>2,U35<=3),"At Risk Customers","Lost Customers"))) -> Loyal or Potential Loyalists
... B2632: C04199 | C2632: 45935 | D2632: 7 | E2632: 2074.2 | G2632: =B2632 -> C04199 | H2632: =C2632 -> 45935 | I2632: =D2632 -> 7 | J2632: =E2632 -> 2074.2 | K2632: =VLOOKUP(H2632,$P$5:$Q$9,2,TRUE) -> 4 | L2632: =VLOOKUP(I2632,$P$12:$Q$16,2,TRUE) -> 5 | M2632: =VLOOKUP(J2632,$P$19:$Q$23,2,TRUE) -> 4 | N2632: =(K2632+L2632+M2632)/3 -> 4.3333333 | S2632: =G2632 -> C04199 | T2632: =$N2632 -> 4.3333333 | U2632: =$N2632 -> 4.3333333 | V2632: =IF(U2632>4,"Champions",IF(AND(U2632>3,U2632<=4),"Loyal or Potential Loyalists",IF(AND(U2632>2,U2632<=3),"At Risk Customers","Lost Customers"))) -> Champions

Sheet DB - Trends
A1: D

Sheet DB - Customers-Products

Sheet DB - RFM
E8: Customer ID | F8: 0 | G8: RFM-Avg | H8: Segment | J8: Segment | K8: Number of Customers | L8: % Composition
E9: {=_xlfn._xlws.FILTER(J17:M2646,M17:M2646=B16,"Choose the Segment")} -> C00039 | F9: 2 | G9: 2 | H9: Lost Customers | J9: Champions | K9: =COUNTIF($M$17:$M$2646,J9) -> 574 | L9: =K9/($K$9+$K$10+$K$11+$K$12) -> 0.21825095
E10: C00049 | F10: 2 | G10: 2 | H10: Lost Customers | J10: Loyal or Potential Loyalists | K10: =COUNTIF($M$17:$M$2646,J10) -> 709 | L10: =K10/($K$9+$K$10+$K$11+$K$12) -> 0.26958175
E11: C00064 | F11: 2 | G11: 2 | H11: Lost Customers | J11: At Risk Customers | K11: =COUNTIF($M$17:$M$2646,J11) -> 924 | L11: =K11/($K$9+$K$10+$K$11+$K$12) -> 0.3513308
E12: C00072 | F12: 1.6666667 | G12: 1.6666667 | H12: Lost Customers | J12: Lost Customers | K12: =COUNTIF($M$17:$M$2646,J12) -> 423 | L12: =K12/($K$9+$K$10+$K$11+$K$12) -> 0.1608365
E13: C00074 | F13: 2 | G13: 2 | H13: Lost Customers
E14: C00083 | F14: 2 | G14: 2 | H14: Lost Customers
E15: C00086 | F15: 2 | G15: 2 | H15: Lost Customers
B16: Lost Customers | E16: C00091 | F16: 2 | G16: 2 | H16: Lost Customers | J16: ='RFM-Pivot'!S2 -> Customer ID | K16: ='RFM-Pivot'!T2 -> 0 | L16: ='RFM-Pivot'!U2 -> RFM-Avg | M16: ='RFM-Pivot'!V2 -> Segment
E17: C00092 | F17: 2 | G17: 2 | H17: Lost Customers | J17: ='RFM-Pivot'!S3 -> C00002 | K17: ='RFM-Pivot'!T3 -> 3.3333333 | L17: ='RFM-Pivot'!U3 -> 3.3333333 | M17: ='RFM-Pivot'!V3 -> Loyal or Potential Loyalists
E18: C00095 | F18: 2 | G18: 2 | H18: Lost Customers | J18: ='RFM-Pivot'!S4 -> C00003 | K18: ='RFM-Pivot'!T4 -> 3.6666667 | L18: ='RFM-Pivot'!U4 -> 3.6666667 | M18: ='RFM-Pivot'!V4 -> Loyal or Potential Loyalists
E19: C00101 | F19: 2 | G19: 2 | H19: Lost Customers | J19: ='RFM-Pivot'!S5 -> C00009 | K19: ='RFM-Pivot'!T5 -> 4 | L19: ='RFM-Pivot'!U5 -> 4 | M19: ='RFM-Pivot'!V5 -> Loyal or Potential Loyalists
E20: C00121 | F20: 1.6666667 | G20: 1.6666667 | H20: Lost Customers | J20: ='RFM-Pivot'!S6 -> C00013 | K20: ='RFM-Pivot'!T6 -> 3 | L20: ='RFM-Pivot'!U6 -> 3 | M20: ='RFM-Pivot'!V6 -> At Risk Customers
E21: C00127 | F21: 1.6666667 | G21: 1.6666667 | H21: Lost Customers | J21: ='RFM-Pivot'!S7 -> C00015 | K21: ='RFM-Pivot'!T7 -> 4.6666667 | L21: ='RFM-Pivot'!U7 -> 4.6666667 | M21: ='RFM-Pivot'!V7 -> Champions
E22: C00130 | F22: 2 | G22: 2 | H22: Lost Customers | J22: ='RFM-Pivot'!S8 -> C00016 | K22: ='RFM-Pivot'!T8 -> 2.6666667 | L22: ='RFM-Pivot'!U8 -> 2.6666667 | M22: ='RFM-Pivot'!V8 -> At Risk Customers
E23: C00139 | F23: 2 | G23: 2 | H23: Lost Customers | J23: ='RFM-Pivot'!S9 -> C00017 | K23: ='RFM-Pivot'!T9 -> 3.3333333 | L23: ='RFM-Pivot'!U9 -> 3.3333333 | M23: ='RFM-Pivot'!V9 -> Loyal or Potential Loyalists
E24: C00141 | F24: 1.6666667 | G24: 1.6666667 | H24: Lost Customers | J24: ='RFM-Pivot'!S10 -> C00018 | K24: ='RFM-Pivot'!T10 -> 2.3333333 | L24: ='RFM-Pivot'!U10 -> 2.3333333 | M24: ='RFM-Pivot'!V10 -> At Risk Customers
E25: C00143 | F25: 2 | G25: 2 | H25: Lost Customers | J25: ='RFM-Pivot'!S11 -> C00019 | K25: ='RFM-Pivot'!T11 -> 3.6666667 | L25: ='RFM-Pivot'!U11 -> 3.6666667 | M25: ='RFM-Pivot'!V11 -> Loyal or Potential Loyalists
